Workbook

Sheet Input
A1: TEE ENTERPRISES(TE)
A2: Number of Years | H2: 0 | I2: 1 | J2: 2 | K2: 3 | L2: 4 | M2: 5 | N2: 6
A3: Start Date | I3: =IF(I2=1,$D$8,H4+1) -> 46753 | J3: =IF(J2=1,$D$8,I4+1) -> 47119 | K3: =IF(K2=1,$D$8,J4+1) -> 47484 | L3: =IF(L2=1,$D$8,K4+1) -> 47849 | M3: =IF(M2=1,$D$8,L4+1) -> 48214 | N3: =IF(N2=1,$D$8,M4+1) -> 48580
A4: End Date | I4: =EDATE(I3,$D$11)-1 -> 47118 | J4: =EDATE(J3,$D$11)-1 -> 47483 | K4: =EDATE(K3,$D$11)-1 -> 47848 | L4: =EDATE(L3,$D$11)-1 -> 48213 | M4: =EDATE(M3,$D$11)-1 -> 48579 | N4: =EDATE(N3,$D$11)-1 -> 48944
A5: Days in A Year | I5: =I4-I3 -> 365 | J5: =J4-J3 -> 364 | K5: =K4-K3 -> 364 | L5: =L4-L3 -> 364 | M5: =M4-M3 -> 365 | N5: =N4-N3 -> 364
A7: General Assumptions
B8: Model Start Date | D8: 46753
B9: Years | D9: 6
B10: Model End Date | D10: =EDATE(D8,D9*D11)-1 -> 48944
B11: Months in a Year | D11: 12
B12: Tax Rate | D12: 0.3
A14: REVENUE ASSUMPTIONS
B15: Pricing
B16: Adire | D16: 40000 | I16: =IF(I$2=1,$D16,H16*(1+$D24)) -> 40000 | J16: =IF(J$2=1,$D16,I16*(1+$D24)) -> 42400 | K16: =IF(K$2=1,$D16,J16*(1+$D24)) -> 44944 | L16: =IF(L$2=1,$D16,K16*(1+$D24)) -> 47640.64 | M16: =IF(M$2=1,$D16,L16*(1+$D24)) -> 50499.078 | N16: =IF(N$2=1,$D16,M16*(1+$D24)) -> 53529.023
B17: Aso-Oke | D17: 22000 | I17: =IF(I$2=1,$D17,H17*(1+$D25)) -> 22000 | J17: =IF(J$2=1,$D17,I17*(1+$D25)) -> 23540 | K17: =IF(K$2=1,$D17,J17*(1+$D25)) -> 25187.8 | L17: =IF(L$2=1,$D17,K17*(1+$D25)) -> 26950.946 | M17: =IF(M$2=1,$D17,L17*(1+$D25)) -> 28837.512 | N17: =IF(N$2=1,$D17,M17*(1+$D25)) -> 30856.138
B18: Plain Tees | D18: 4000 | I18: =IF(I$2=1,$D18,H18*(1+$D26)) -> 4000 | J18: =IF(J$2=1,$D18,I18*(1+$D26)) -> 4200 | K18: =IF(K$2=1,$D18,J18*(1+$D26)) -> 4410 | L18: =IF(L$2=1,$D18,K18*(1+$D26)) -> 4630.5 | M18: =IF(M$2=1,$D18,L18*(1+$D26)) -> 4862.025 | N18: =IF(N$2=1,$D18,M18*(1+$D26)) -> 5105.1263
B19: Jeans | D19: 30000 | I19: =IF(I$2=1,$D19,H19*(1+$D27)) -> 30000 | J19: =IF(J$2=1,$D19,I19*(1+$D27)) -> 32400 | K19: =IF(K$2=1,$D19,J19*(1+$D27)) -> 34992 | L19: =IF(L$2=1,$D19,K19*(1+$D27)) -> 37791.36 | M19: =IF(M$2=1,$D19,L19*(1+$D27)) -> 40814.669 | N19: =IF(N$2=1,$D19,M19*(1+$D27)) -> 44079.842
B20: Crop Top | D20: 7000 | I20: =IF(I$2=1,$D20,H20*(1+$D28)) -> 7000 | J20: =IF(J$2=1,$D20,I20*(1+$D28)) -> 7770 | K20: =IF(K$2=1,$D20,J20*(1+$D28)) -> 8624.7 | L20: =IF(L$2=1,$D20,K20*(1+$D28)) -> 9573.417 | M20: =IF(M$2=1,$D20,L20*(1+$D28)) -> 10626.493 | N20: =IF(N$2=1,$D20,M20*(1+$D28)) -> 11795.407
B21: Aprons | D21: 9000 | I21: =IF(I$2=1,$D21,H21*(1+$D29)) -> 9000 | J21: =IF(J$2=1,$D21,I21*(1+$D29)) -> 9270 | K21: =IF(K$2=1,$D21,J21*(1+$D29)) -> 9548.1 | L21: =IF(L$2=1,$D21,K21*(1+$D29)) -> 9834.543 | M21: =IF(M$2=1,$D21,L21*(1+$D29)) -> 10129.579 | N21: =IF(N$2=1,$D21,M21*(1+$D29)) -> 10433.467
B23: Price Increase Rate
B24: Adire | D24: 0.06
B25: Aso-Oke | D25: 0.07
B26: Plain Tees | D26: 0.05
B27: Jeans | D27: 0.08
B28: Crop Top | D28: 0.11
B29: Aprons | D29: 0.03
B31: Sales Volume
B32: Adire | D32: 99 | I32: =IF(I$2=1,$D32,H32*(1+$D40)) -> 99 | J32: =IF(J$2=1,$D32,I32*(1+$D40)) -> 108.9 | K32: =IF(K$2=1,$D32,J32*(1+$D40)) -> 119.79 | L32: =IF(L$2=1,$D32,K32*(1+$D40)) -> 131.769 | M32: =IF(M$2=1,$D32,L32*(1+$D40)) -> 144.9459 | N32: =IF(N$2=1,$D32,M32*(1+$D40)) -> 159.44049
B33: Aso-Oke | D33: 34 | I33: =IF(I$2=1,$D33,H33*(1+$D41)) -> 34 | J33: =IF(J$2=1,$D33,I33*(1+$D41)) -> 37.06 | K33: =IF(K$2=1,$D33,J33*(1+$D41)) -> 40.3954 | L33: =IF(L$2=1,$D33,K33*(1+$D41)) -> 44.030986 | M33: =IF(M$2=1,$D33,L33*(1+$D41)) -> 47.993775 | N33: =IF(N$2=1,$D33,M33*(1+$D41)) -> 52.313214
B34: Plain Tees | D34: 92 | I34: =IF(I$2=1,$D34,H34*(1+$D42)) -> 92 | J34: =IF(J$2=1,$D34,I34*(1+$D42)) -> 103.96 | K34: =IF(K$2=1,$D34,J34*(1+$D42)) -> 117.4748 | L34: =IF(L$2=1,$D34,K34*(1+$D42)) -> 132.74652 | M34: =IF(M$2=1,$D34,L34*(1+$D42)) -> 150.00357 | N34: =IF(N$2=1,$D34,M34*(1+$D42)) -> 169.50404
B35: Jeans | D35: 43 | I35: =IF(I$2=1,$D35,H35*(1+$D43)) -> 43 | J35: =IF(J$2=1,$D35,I35*(1+$D43)) -> 46.01 | K35: =IF(K$2=1,$D35,J35*(1+$D43)) -> 49.2307 | L35: =IF(L$2=1,$D35,K35*(1+$D43)) -> 52.676849 | M35: =IF(M$2=1,$D35,L35*(1+$D43)) -> 56.364228 | N35: =IF(N$2=1,$D35,M35*(1+$D43)) -> 60.309724
B36: Crop Top | D36: 90 | I36: =IF(I$2=1,$D36,H36*(1+$D44)) -> 90 | J36: =IF(J$2=1,$D36,I36*(1+$D44)) -> 99 | K36: =IF(K$2=1,$D36,J36*(1+$D44)) -> 108.9 | L36: =IF(L$2=1,$D36,K36*(1+$D44)) -> 119.79 | M36: =IF(M$2=1,$D36,L36*(1+$D44)) -> 131.769 | N36: =IF(N$2=1,$D36,M36*(1+$D44)) -> 144.9459
B37: Aprons | D37: 88 | I37: =IF(I$2=1,$D37,H37*(1+$D45)) -> 88 | J37: =IF(J$2=1,$D37,I37*(1+$D45)) -> 95.04 | K37: =IF(K$2=1,$D37,J37*(1+$D45)) -> 102.6432 | L37: =IF(L$2=1,$D37,K37*(1+$D45)) -> 110.85466 | M37: =IF(M$2=1,$D37,L37*(1+$D45)) -> 119.72303 | N37: =IF(N$2=1,$D37,M37*(1+$D45)) -> 129.30087
B39: Growth Rate
B40: Adire | D40: 0.1
B41: Aso-Oke | D41: 0.09
B42: Plain Tees | D42: 0.13
B43: Jeans | D43: 0.07
B44: Crop Top | D44: 0.1
B45: Aprons | D45: 0.08
...

Sheet Workings
A1: TEE ENTERPRISES(TE)
A2: Number of Years | H2: 0 | I2: 1 | J2: 2 | K2: 3 | L2: 4 | M2: 5 | N2: 6
A3: Start Date | I3: =IF(I2=1,$D$8,H4+1) -> 46753 | J3: =IF(J2=1,$D$8,I4+1) -> 47119 | K3: =IF(K2=1,$D$8,J4+1) -> 47484 | L3: =IF(L2=1,$D$8,K4+1) -> 47849 | M3: =IF(M2=1,$D$8,L4+1) -> 48214 | N3: =IF(N2=1,$D$8,M4+1) -> 48580
A4: End Date | I4: =EDATE(I3,$D$11)-1 -> 47118 | J4: =EDATE(J3,$D$11)-1 -> 47483 | K4: =EDATE(K3,$D$11)-1 -> 47848 | L4: =EDATE(L3,$D$11)-1 -> 48213 | M4: =EDATE(M3,$D$11)-1 -> 48579 | N4: =EDATE(N3,$D$11)-1 -> 48944
A5: Days in A Year | I5: =I4-I3 -> 365 | J5: =J4-J3 -> 364 | K5: =K4-K3 -> 364 | L5: =L4-L3 -> 364 | M5: =M4-M3 -> 365 | N5: =N4-N3 -> 364
A7: General Assumptions
B8: Model Start Date | D8: 46753
B9: Years | D9: 6
B10: Model End Date | D10: =EDATE(D8,D9*D11)-1 -> 48944
B11: Months in a Year | D11: 12
B12: Tax Rate | D12: 0.3
A14: REVENUE
B16: Volume
B17: Adire | I17: =Input!I32 -> 99 | J17: =Input!J32 -> 108.9 | K17: =Input!K32 -> 119.79 | L17: =Input!L32 -> 131.769 | M17: =Input!M32 -> 144.9459 | N17: =Input!N32 -> 159.44049
B18: Aso-Oke | I18: =Input!I33 -> 34 | J18: =Input!J33 -> 37.06 | K18: =Input!K33 -> 40.3954 | L18: =Input!L33 -> 44.030986 | M18: =Input!M33 -> 47.993775 | N18: =Input!N33 -> 52.313214
B19: Plain Tees | I19: =Input!I34 -> 92 | J19: =Input!J34 -> 103.96 | K19: =Input!K34 -> 117.4748 | L19: =Input!L34 -> 132.74652 | M19: =Input!M34 -> 150.00357 | N19: =Input!N34 -> 169.50404
B20: Jeans | I20: =Input!I35 -> 43 | J20: =Input!J35 -> 46.01 | K20: =Input!K35 -> 49.2307 | L20: =Input!L35 -> 52.676849 | M20: =Input!M35 -> 56.364228 | N20: =Input!N35 -> 60.309724
B21: Crop Top | I21: =Input!I36 -> 90 | J21: =Input!J36 -> 99 | K21: =Input!K36 -> 108.9 | L21: =Input!L36 -> 119.79 | M21: =Input!M36 -> 131.769 | N21: =Input!N36 -> 144.9459
B22: Aprons | I22: =Input!I37 -> 88 | J22: =Input!J37 -> 95.04 | K22: =Input!K37 -> 102.6432 | L22: =Input!L37 -> 110.85466 | M22: =Input!M37 -> 119.72303 | N22: =Input!N37 -> 129.30087
B24: Price
B25: Adire | I25: =Input!I16 -> 40000 | J25: =Input!J16 -> 42400 | K25: =Input!K16 -> 44944 | L25: =Input!L16 -> 47640.64 | M25: =Input!M16 -> 50499.078 | N25: =Input!N16 -> 53529.023
B26: Aso-Oke | I26: =Input!I17 -> 22000 | J26: =Input!J17 -> 23540 | K26: =Input!K17 -> 25187.8 | L26: =Input!L17 -> 26950.946 | M26: =Input!M17 -> 28837.512 | N26: =Input!N17 -> 30856.138
B27: Plain Tees | I27: =Input!I18 -> 4000 | J27: =Input!J18 -> 4200 | K27: =Input!K18 -> 4410 | L27: =Input!L18 -> 4630.5 | M27: =Input!M18 -> 4862.025 | N27: =Input!N18 -> 5105.1263
B28: Jeans | I28: =Input!I19 -> 30000 | J28: =Input!J19 -> 32400 | K28: =Input!K19 -> 34992 | L28: =Input!L19 -> 37791.36 | M28: =Input!M19 -> 40814.669 | N28: =Input!N19 -> 44079.842
B29: Crop Top | I29: =Input!I20 -> 7000 | J29: =Input!J20 -> 7770 | K29: =Input!K20 -> 8624.7 | L29: =Input!L20 -> 9573.417 | M29: =Input!M20 -> 10626.493 | N29: =Input!N20 -> 11795.407
B30: Aprons | I30: =Input!I21 -> 9000 | J30: =Input!J21 -> 9270 | K30: =Input!K21 -> 9548.1 | L30: =Input!L21 -> 9834.543 | M30: =Input!M21 -> 10129.579 | N30: =Input!N21 -> 10433.467
B32: Total
B33: Adire | I33: =I17*I25 -> 3960000 | J33: =J17*J25 -> 4617360 | K33: =K17*K25 -> 5383841.8 | L33: =L17*L25 -> 6277559.5 | M33: =M17*M25 -> 7319634.4 | N33: =N17*N25 -> 8534693.7
B34: Aso-Oke | I34: =I18*I26 -> 748000 | J34: =J18*J26 -> 872392.4 | K34: =K18*K26 -> 1017471.3 | L34: =L18*L26 -> 1186676.7 | M34: =M18*M26 -> 1384021.1 | N34: =N18*N26 -> 1614183.8
B35: Plain Tees | I35: =I19*I27 -> 368000 | J35: =J19*J27 -> 436632 | K35: =K19*K27 -> 518063.87 | L35: =L19*L27 -> 614682.78 | M35: =M19*M27 -> 729321.12 | N35: =N19*N27 -> 865339.51
B36: Jeans | I36: =I20*I28 -> 1290000 | J36: =J20*J28 -> 1490724 | K36: =K20*K28 -> 1722680.7 | L36: =L20*L28 -> 1990729.8 | M36: =M20*M28 -> 2300487.3 | N36: =N20*N28 -> 2658443.1
B37: Crop Top | I37: =I21*I29 -> 630000 | J37: =J21*J29 -> 769230 | K37: =K21*K29 -> 939229.83 | L37: =L21*L29 -> 1146799.6 | M37: =M21*M29 -> 1400242.3 | N37: =N21*N29 -> 1709695.9
B38: Aprons | I38: =I22*I30 -> 792000 | J38: =J22*J30 -> 881020.8 | K38: =K22*K30 -> 980047.54 | L38: =L22*L30 -> 1090204.9 | M38: =M22*M30 -> 1212743.9 | N38: =N22*N30 -> 1349056.3
B39: TOTAL REVENUE | I39: =SUM(I33:I38) -> 7788000 | J39: =SUM(J33:J38) -> 9067359.2 | K39: =SUM(K33:K38) -> 10561335 | L39: =SUM(L33:L38) -> 12306653 | M39: =SUM(M33:M38) -> 14346450 | N39: =SUM(N33:N38) -> 16731412
A41: DIRECT COST ASSUMPTIONS
B43: Costs
B44: Adire | I44: =Input!I50 -> 30000 | J44: =Input!J50 -> 30900 | K44: =Input!K50 -> 31827 | L44: =Input!L50 -> 32781.81 | M44: =Input!M50 -> 33765.264 | N44: =Input!N50 -> 34778.222
B45: Aso-Oke | I45: =Input!I51 -> 19000 | J45: =Input!J51 -> 19950 | K45: =Input!K51 -> 20947.5 | L45: =Input!L51 -> 21994.875 | M45: =Input!M51 -> 23094.619 | N45: =Input!N51 -> 24249.35
B46: Plain Tees | I46: =Input!I52 -> 3000 | J46: =Input!J52 -> 3120 | K46: =Input!K52 -> 3244.8 | L46: =Input!L52 -> 3374.592 | M46: =Input!M52 -> 3509.5757 | N46: =Input!N52 -> 3649.9587
B47: Jeans | I47: =Input!I53 -> 21000 | J47: =Input!J53 -> 21840 | K47: =Input!K53 -> 22713.6 | L47: =Input!L53 -> 23622.144 | M47: =Input!M53 -> 24567.03 | N47: =Input!N53 -> 25549.711
...

Sheet Income Statement
A1: TEE ENTERPRISES(TE)
A2: Number of Years | H2: 0 | I2: 1 | J2: 2 | K2: 3 | L2: 4 | M2: 5 | N2: 6
A3: Start Date | I3: =Input!I3 -> 46753 | J3: =Input!J3 -> 47119 | K3: =Input!K3 -> 47484 | L3: =Input!L3 -> 47849 | M3: =Input!M3 -> 48214 | N3: =Input!N3 -> 48580
A4: End Date | I4: =Input!I4 -> 47118 | J4: =Input!J4 -> 47483 | K4: =Input!K4 -> 47848 | L4: =Input!L4 -> 48213 | M4: =Input!M4 -> 48579 | N4: =Input!N4 -> 48944
A5: Days in A Year | I5: =I4-I3 -> 365 | J5: =J4-J3 -> 364 | K5: =K4-K3 -> 364 | L5: =L4-L3 -> 364 | M5: =M4-M3 -> 365 | N5: =N4-N3 -> 364
A7: INCOME STATEMENT
B8: Revenue | I8: =Workings!I39 -> 7788000 | J8: =Workings!J39 -> 9067359.2 | K8: =Workings!K39 -> 10561335 | L8: =Workings!L39 -> 12306653 | M8: =Workings!M39 -> 14346450 | N8: =Workings!N39 -> 16731412
B9: Direct Cost | I9: =Workings!I58 -> 5595000 | J9: =Workings!J58 -> 6345954.6 | K9: =Workings!K58 -> 7200161.4 | L9: =Workings!L58 -> 8172190.7 | M9: =Workings!M58 -> 9278726.5 | N9: =Workings!N58 -> 10538882
B10: Gross Profit | I10: =I8-I9 -> 2193000 | J10: =J8-J9 -> 2721404.6 | K10: =K8-K9 -> 3361173.5 | L10: =L8-L9 -> 4134462.6 | M10: =M8-M9 -> 5067723.6 | N10: =N8-N9 -> 6192530
B11: Operating Expenses (OPEX) | I11: =Workings!I73 -> 1139400 | J11: =Workings!J73 -> 1203368 | K11: =Workings!K73 -> 1278066.7 | L11: =Workings!L73 -> 1365332.7 | M11: =Workings!M73 -> 1467322.5 | N11: =Workings!N73 -> 1586570.6
B12: EBITDA | I12: =I10-I11 -> 1053600 | J12: =J10-J11 -> 1518036.6 | K12: =K10-K11 -> 2083106.8 | L12: =L10-L11 -> 2769129.9 | M12: =M10-M11 -> 3600401.1 | N12: =N10-N11 -> 4605959.3
B13: Depreciation & Amortization | I13: =Workings!I124 -> 1250000 | J13: =Workings!J124 -> 1250000 | K13: =Workings!K124 -> 1250000 | L13: =Workings!L124 -> 1250000 | M13: =Workings!M124 -> 1250000 | N13: =Workings!N124 -> 450000
B14: EBIT | I14: =I12-I13 -> -196400 | J14: =J12-J13 -> 268036.64 | K14: =K12-K13 -> 833106.76 | L14: =L12-L13 -> 1519129.9 | M14: =M12-M13 -> 2350401.1 | N14: =N12-N13 -> 4155959.3
B15: Interest Expenses | I15: =Workings!I137 -> 900000 | J15: =Workings!J137 -> 797186.78 | K15: =Workings!K137 -> 678951.59 | L15: =Workings!L137 -> 542981.11 | M15: =Workings!M137 -> 386615.06 | N15: =Workings!N137 -> 206794.1
B16: Profit Before Tax | I16: =I14-I15 -> -1096400 | J16: =J14-J15 -> -529150.14 | K16: =K14-K15 -> 154155.18 | L16: =L14-L15 -> 976148.83 | M16: =M14-M15 -> 1963786.1 | N16: =N14-N15 -> 3949165.2
B17: Tax | I17: =IF(I16>0,Input!$D$12*'Income Statement'!I16,0) -> 0 | J17: =IF(J16>0,Input!$D$12*'Income Statement'!J16,0) -> 0 | K17: =IF(K16>0,Input!$D$12*'Income Statement'!K16,0) -> 46246.554 | L17: =IF(L16>0,Input!$D$12*'Income Statement'!L16,0) -> 292844.65 | M17: =IF(M16>0,Input!$D$12*'Income Statement'!M16,0) -> 589135.82 | N17: =IF(N16>0,Input!$D$12*'Income Statement'!N16,0) -> 1184749.6
B18: Profit After Tax | I18: =I16-I17 -> -1096400 | J18: =J16-J17 -> -529150.14 | K18: =K16-K17 -> 107908.63 | L18: =L16-L17 -> 683304.18 | M18: =M16-M17 -> 1374650.3 | N18: =N16-N17 -> 2764415.7

Sheet Statement of Cash Flows
A1: TEE ENTERPRISES(TE)
A2: Number of Years | H2: 0 | I2: 1 | J2: 2 | K2: 3 | L2: 4 | M2: 5 | N2: 6
A3: Start Date | I3: =Input!I3 -> 46753 | J3: =Input!J3 -> 47119 | K3: =Input!K3 -> 47484 | L3: =Input!L3 -> 47849 | M3: =Input!M3 -> 48214 | N3: =Input!N3 -> 48580
A4: End Date | I4: =Input!I4 -> 47118 | J4: =Input!J4 -> 47483 | K4: =Input!K4 -> 47848 | L4: =Input!L4 -> 48213 | M4: =Input!M4 -> 48579 | N4: =Input!N4 -> 48944
A5: Days in A Year | I5: =I4-I3 -> 365 | J5: =J4-J3 -> 364 | K5: =K4-K3 -> 364 | L5: =L4-L3 -> 364 | M5: =M4-M3 -> 365 | N5: =N4-N3 -> 364
A7: CASHFLOW STATEMENT
B8: Operating Activities
C9: EBITDA | I9: ='Income Statement'!I12 -> 1053600 | J9: ='Income Statement'!J12 -> 1518036.6 | K9: ='Income Statement'!K12 -> 2083106.8 | L9: ='Income Statement'!L12 -> 2769129.9 | M9: ='Income Statement'!M12 -> 3600401.1 | N9: ='Income Statement'!N12 -> 4605959.3
C10: Changes in Working Capital:
C11: Changes in receivables from Customers | I11: =SOFP!H16-SOFP!I16 -> -213369.86 | J11: =SOFP!I16-SOFP!J16 -> -35733.412 | K11: =SOFP!J16-SOFP!K16 -> -41043.289 | L11: =SOFP!K16-SOFP!L16 -> -47948.307 | M11: =SOFP!L16-SOFP!M16 -> -54958.558 | N11: =SOFP!M16-SOFP!N16 -> -66600.757
C12: Changes in Payables | I12: =SOFP!I28-SOFP!H28 -> 128021.92 | J12: =SOFP!J28-SOFP!I28 -> 21440.047 | K12: =SOFP!K28-SOFP!J28 -> 24625.973 | L12: =SOFP!L28-SOFP!K28 -> 28768.984 | M12: =SOFP!M28-SOFP!L28 -> 32975.135 | N12: =SOFP!N28-SOFP!M28 -> 39960.454
C13: Changes in Inventory | I13: =SOFP!H17-SOFP!I17 -> -76643.836 | J13: =SOFP!I17-SOFP!J17 -> -10525.87 | K13: =SOFP!J17-SOFP!K17 -> -11733.61 | L13: =SOFP!K17-SOFP!L17 -> -13352.05 | M13: =SOFP!L17-SOFP!M17 -> -14850.476 | N13: =SOFP!M17-SOFP!N17 -> -17659.025
B14: Changes in Working Capital | I14: =SUM(I11:I13) -> -161991.78 | J14: =SUM(J11:J13) -> -24819.235 | K14: =SUM(K11:K13) -> -28150.925 | L14: =SUM(L11:L13) -> -32531.373 | M14: =SUM(M11:M13) -> -36833.899 | N14: =SUM(N11:N13) -> -44299.328
B15: Tax Paid | I15: =-'Income Statement'!H17 -> 0 | J15: =-'Income Statement'!I17 -> 0 | K15: =-'Income Statement'!J17 -> 0 | L15: =-'Income Statement'!K17 -> -46246.554 | M15: =-'Income Statement'!L17 -> -292844.65 | N15: =-'Income Statement'!M17 -> -589135.82
B16: Cash From Operating Activities | I16: =SUM(I14:I15)+I9 -> 891608.22 | J16: =SUM(J14:J15)+J9 -> 1493217.4 | K16: =SUM(K14:K15)+K9 -> 2054955.8 | L16: =SUM(L14:L15)+L9 -> 2690352 | M16: =SUM(M14:M15)+M9 -> 3270722.6 | N16: =SUM(N14:N15)+N9 -> 3972524.2
B18: Investing Activities
C19: Acquisition/Disposal of Assets | I19: =-Workings!I117 -> -8500000 | J19: =-Workings!J117 -> 0 | K19: =-Workings!K117 -> 0 | L19: =-Workings!L117 -> 0 | M19: =-Workings!M117 -> 0 | N19: =-Workings!N117 -> 0
B21: Cash From Investing Activities | H21: - | I21: =I19 -> -8500000 | J21: =J19 -> 0 | K21: =K19 -> 0 | L21: =L19 -> 0 | M21: =M19 -> 0 | N21: =N19 -> 0
B24: Financing Activities
C25: Drawdown From Loan | I25: =Workings!I136 -> 6000000 | J25: =Workings!J136 -> 0 | K25: =Workings!K136 -> 0 | L25: =Workings!L136 -> 0 | M25: =Workings!M136 -> 0 | N25: =Workings!N136 -> 0
C26: Repayment of Borrowings | I26: =-Workings!I138 -> -1585421.4 | J26: =-Workings!J138 -> -1585421.4 | K26: =-Workings!K138 -> -1585421.4 | L26: =-Workings!L138 -> -1585421.4 | M26: =-Workings!M138 -> -1585421.4 | N26: =-Workings!N138 -> -1585421.4
C27: Equity Injection | I27: =Workings!I144 -> 9000000 | J27: =Workings!J144 -> 0 | K27: =Workings!K144 -> 0 | L27: =Workings!L144 -> 0 | M27: =Workings!M144 -> 0 | N27: =Workings!N144 -> 0
C28: Dividend Payment | I28: 0 | J28: 0 | K28: 0 | L28: 0 | M28: 0 | N28: 0
B29: Cash From Financing Activities | I29: =SUM(I25:I28) -> 13414579 | J29: =SUM(J25:J28) -> -1585421.4 | K29: =SUM(K25:K28) -> -1585421.4 | L29: =SUM(L25:L28) -> -1585421.4 | M29: =SUM(M25:M28) -> -1585421.4 | N29: =SUM(N25:N28) -> -1585421.4
B31: Net Cash Generated/Spent During The Period | I31: =I29+I21+I16 -> 5806186.8 | J31: =J29+J21+J16 -> -92204.035 | K31: =K29+K21+K16 -> 469534.4 | L31: =L29+L21+L16 -> 1104930.6 | M31: =M29+M21+M16 -> 1685301.1 | N31: =N29+N21+N16 -> 2387102.8
B32: Cash AT The Beginning Of The Period | I32: =H33 -> 0 | J32: =I33 -> 5806186.8 | K32: =J33 -> 5713982.7 | L32: =K33 -> 6183517.1 | M32: =L33 -> 7288447.7 | N32: =M33 -> 8973748.9
B33: Closing Balance | I33: =SUM(I31:I32) -> 5806186.8 | J33: =SUM(J31:J32) -> 5713982.7 | K33: =SUM(K31:K32) -> 6183517.1 | L33: =SUM(L31:L32) -> 7288447.7 | M33: =SUM(M31:M32) -> 8973748.9 | N33: =SUM(N31:N32) -> 11360852

Sheet SOFP
A1: TEE ENTERPRISES(TE)
A2: Number of Years | H2: 0 | I2: 1 | J2: 2 | K2: 3 | L2: 4 | M2: 5 | N2: 6
A3: Start Date | I3: =Input!I3 -> 46753 | J3: =Input!J3 -> 47119 | K3: =Input!K3 -> 47484 | L3: =Input!L3 -> 47849 | M3: =Input!M3 -> 48214 | N3: =Input!N3 -> 48580
A4: End Date | I4: =Input!I4 -> 47118 | J4: =Input!J4 -> 47483 | K4: =Input!K4 -> 47848 | L4: =Input!L4 -> 48213 | M4: =Input!M4 -> 48579 | N4: =Input!N4 -> 48944
A5: Days in A Year | I5: =I4-I3 -> 365 | J5: =J4-J3 -> 364 | K5: =K4-K3 -> 364 | L5: =L4-L3 -> 364 | M5: =M4-M3 -> 365 | N5: =N4-N3 -> 364
A7: STATEMENT OF FINANCIAL POSITION
B8: Non-Current Asset
B9: Furnitures and Fittings | I9: =Workings!I88 -> 1600000 | J9: =Workings!J88 -> 1200000 | K9: =Workings!K88 -> 800000 | L9: =Workings!L88 -> 400000 | M9: =Workings!M88 -> 0 | N9: =Workings!N88 -> 0
B10: Motor Vehicle | I10: =Workings!I95 -> 3150000 | J10: =Workings!J95 -> 2800000 | K10: =Workings!K95 -> 2450000 | L10: =Workings!L95 -> 2100000 | M10: =Workings!M95 -> 1750000 | N10: =Workings!N95 -> 1400000
B11: Clothing Equipment | I11: =Workings!I103 -> 1600000 | J11: =Workings!J103 -> 1200000 | K11: =Workings!K103 -> 800000 | L11: =Workings!L103 -> 400000 | M11: =Workings!M103 -> 0 | N11: =Workings!N103 -> 0
B12: Industrial Sewing Machine | I12: =Workings!I110 -> 900000 | J12: =Workings!J110 -> 800000 | K12: =Workings!K110 -> 700000 | L12: =Workings!L110 -> 600000 | M12: =Workings!M110 -> 500000 | N12: =Workings!N110 -> 400000
B13: Total Non-Current Assets | I13: =SUM(I9:I12) -> 7250000 | J13: =SUM(J9:J12) -> 6000000 | K13: =SUM(K9:K12) -> 4750000 | L13: =SUM(L9:L12) -> 3500000 | M13: =SUM(M9:M12) -> 2250000 | N13: =SUM(N9:N12) -> 1800000
B15: Current Assets
B16: Receivables | I16: =Workings!I78 -> 213369.86 | J16: =Workings!J78 -> 249103.27 | K16: =Workings!K78 -> 290146.56 | L16: =Workings!L78 -> 338094.87 | M16: =Workings!M78 -> 393053.43 | N16: =Workings!N78 -> 459654.18
B17: Inventories | I17: =Workings!I80 -> 76643.836 | J17: =Workings!J80 -> 87169.706 | K17: =Workings!K80 -> 98903.316 | L17: =Workings!L80 -> 112255.37 | M17: =Workings!M80 -> 127105.84 | N17: =Workings!N80 -> 144764.87
B18: Cash | I18: ='Statement of Cash Flows'!I33 -> 5806186.8 | J18: ='Statement of Cash Flows'!J33 -> 5713982.7 | K18: ='Statement of Cash Flows'!K33 -> 6183517.1 | L18: ='Statement of Cash Flows'!L33 -> 7288447.7 | M18: ='Statement of Cash Flows'!M33 -> 8973748.9 | N18: ='Statement of Cash Flows'!N33 -> 11360852
B19: Total Current Assets | I19: =SUM(I16:I18) -> 6096200.5 | J19: =SUM(J16:J18) -> 6050255.7 | K19: =SUM(K16:K18) -> 6572567 | L19: =SUM(L16:L18) -> 7738798 | M19: =SUM(M16:M18) -> 9493908.1 | N19: =SUM(N16:N18) -> 11965271
A21: TOTAL ASSETS | I21: =I19+I13 -> 13346200 | J21: =J19+J13 -> 12050256 | K21: =K19+K13 -> 11322567 | L21: =L19+L13 -> 11238798 | M21: =M19+M13 -> 11743908 | N21: =N19+N13 -> 13765271
B23: Non-Current Liabilities
B24: Borrowings | I24: =Workings!I139 -> 5314578.6 | J24: =Workings!J139 -> 4526343.9 | K24: =Workings!K139 -> 3619874.1 | L24: =Workings!L139 -> 2577433.7 | M24: =Workings!M139 -> 1378627.3 | N24: =Workings!N139 -> 0
B25: Total Non-Current Liabilities | I25: =SUM(I24) -> 5314578.6 | J25: =SUM(J24) -> 4526343.9 | K25: =SUM(K24) -> 3619874.1 | L25: =SUM(L24) -> 2577433.7 | M25: =SUM(M24) -> 1378627.3 | N25: =SUM(N24) -> 0
B27: Current Liabilties
B28: Payables | I28: =Workings!I79 -> 128021.92 | J28: =Workings!J79 -> 149461.96 | K28: =Workings!K79 -> 174087.94 | L28: =Workings!L79 -> 202856.92 | M28: =Workings!M79 -> 235832.06 | N28: =Workings!N79 -> 275792.51
B29: Tax Payable | I29: ='Income Statement'!I17 -> 0 | J29: ='Income Statement'!J17 -> 0 | K29: ='Income Statement'!K17 -> 46246.554 | L29: ='Income Statement'!L17 -> 292844.65 | M29: ='Income Statement'!M17 -> 589135.82 | N29: ='Income Statement'!N17 -> 1184749.6
B30: Total Current Liabilties | I30: =SUM(I28:I29) -> 128021.92 | J30: =SUM(J28:J29) -> 149461.96 | K30: =SUM(K28:K29) -> 220334.49 | L30: =SUM(L28:L29) -> 495701.57 | M30: =SUM(M28:M29) -> 824967.88 | N30: =SUM(N28:N29) -> 1460542.1
A32: Equity
B33: Share Capital | I33: =Workings!I145 -> 9000000 | J33: =Workings!J145 -> 9000000 | K33: =Workings!K145 -> 9000000 | L33: =Workings!L145 -> 9000000 | M33: =Workings!M145 -> 9000000 | N33: =Workings!N145 -> 9000000
B34: Share Premium
B35: Retained Earnings | I35: =Workings!I151 -> -1096400 | J35: =Workings!J151 -> -1625550.1 | K35: =Workings!K151 -> -1517641.5 | L35: =Workings!L151 -> -834337.34 | M35: =Workings!M151 -> 540312.91 | N35: =Workings!N151 -> 3304728.6
B36: Total Equity | I36: =SUM(I33:I35) -> 7903600 | J36: =SUM(J33:J35) -> 7374449.9 | K36: =SUM(K33:K35) -> 7482358.5 | L36: =SUM(L33:L35) -> 8165662.7 | M36: =SUM(M33:M35) -> 9540312.9 | N36: =SUM(N33:N35) -> 12304729
B38: TOTAL EQUITY AND LIABILITIES | I38: =I36+I30+I25 -> 13346200 | J38: =J36+J30+J25 -> 12050256 | K38: =K36+K30+K25 -> 11322567 | L38: =L36+L30+L25 -> 11238798 | M38: =M36+M30+M25 -> 11743908 | N38: =N36+N30+N25 -> 13765271
